[2024-11-10T05:12:45.135+0000] {taskinstance.py:1125} INFO - Dependencies all met for dep_context=non-requeueable deps ti=<TaskInstance: weather_etl.transform manual__2024-11-10T05:07:41.236799+00:00 [queued]>
[2024-11-10T05:12:45.144+0000] {taskinstance.py:1125} INFO - Dependencies all met for dep_context=requeueable deps ti=<TaskInstance: weather_etl.transform manual__2024-11-10T05:07:41.236799+00:00 [queued]>
[2024-11-10T05:12:45.145+0000] {taskinstance.py:1331} INFO - Starting attempt 2 of 2
[2024-11-10T05:12:45.155+0000] {taskinstance.py:1350} INFO - Executing <Task(PythonOperator): transform> on 2024-11-10 05:07:41.236799+00:00
[2024-11-10T05:12:45.159+0000] {standard_task_runner.py:57} INFO - Started process 63 to run task
[2024-11-10T05:12:45.163+0000] {standard_task_runner.py:84} INFO - Running: ['***', 'tasks', 'run', 'weather_etl', 'transform', 'manual__2024-11-10T05:07:41.236799+00:00', '--job-id', '16', '--raw', '--subdir', 'DAGS_FOLDER/weather_etl_dag.py', '--cfg-path', '/tmp/tmp3d6k91p4']
[2024-11-10T05:12:45.165+0000] {standard_task_runner.py:85} INFO - Job 16: Subtask transform
[2024-11-10T05:12:45.177+0000] {warnings.py:110} WARNING - /home/***/.local/lib/python3.7/site-packages/***/settings.py:188: DeprecationWarning: The sql_alchemy_conn option in [core] has been moved to the sql_alchemy_conn option in [database] - the old setting has been used, but please update your config.
  SQL_ALCHEMY_CONN = conf.get("database", "SQL_ALCHEMY_CONN")

[2024-11-10T05:12:45.204+0000] {task_command.py:410} INFO - Running <TaskInstance: weather_etl.transform manual__2024-11-10T05:07:41.236799+00:00 [running]> on host 92a0155041c8
[2024-11-10T05:12:45.515+0000] {taskinstance.py:1570} INFO - Exporting env vars: AIRFLOW_CTX_DAG_OWNER='***' AIRFLOW_CTX_DAG_ID='weather_etl' AIRFLOW_CTX_TASK_ID='transform' AIRFLOW_CTX_EXECUTION_DATE='2024-11-10T05:07:41.236799+00:00' AIRFLOW_CTX_TRY_NUMBER='2' AIRFLOW_CTX_DAG_RUN_ID='manual__2024-11-10T05:07:41.236799+00:00'
[2024-11-10T05:12:45.524+0000] {taskinstance.py:1847} ERROR - Task failed with exception
Traceback (most recent call last):
  File "/home/airflow/.local/lib/python3.7/site-packages/airflow/operators/python.py", line 181, in execute
    return_value = self.execute_callable()
  File "/home/airflow/.local/lib/python3.7/site-packages/airflow/operators/python.py", line 198, in execute_callable
    return self.python_callable(*self.op_args, **self.op_kwargs)
  File "/opt/airflow/dags/weather_etl_dag.py", line 50, in transform_task
    df = transform_data(data)
  File "/opt/airflow/dags/scripts/transform.py", line 8, in transform_data
    if not all(key in data for key in ['city', 'temperature', 'humidity', 'weather']):
  File "/opt/airflow/dags/scripts/transform.py", line 8, in <genexpr>
    if not all(key in data for key in ['city', 'temperature', 'humidity', 'weather']):
TypeError: argument of type 'NoneType' is not iterable
[2024-11-10T05:12:45.531+0000] {taskinstance.py:1373} INFO - Marking task as FAILED. dag_id=weather_etl, task_id=transform, execution_date=20241110T050741, start_date=20241110T051245, end_date=20241110T051245
[2024-11-10T05:12:45.539+0000] {standard_task_runner.py:109} ERROR - Failed to execute job 16 for task transform (argument of type 'NoneType' is not iterable; 63)
[2024-11-10T05:12:45.565+0000] {local_task_job_runner.py:232} INFO - Task exited with return code 1
[2024-11-10T05:12:45.585+0000] {taskinstance.py:2674} INFO - 0 downstream tasks scheduled from follow-on schedule check
